Workbook

Sheet Leia-me
A1: LEIA-ME — fontes, limitações e o que mudou
A3: O QUE ESTAVA ERRADO NO RELATÓRIO ANTERIOR
A4: Resumo não fechava com as abas | B4: O Resumo trazia 6.830 peças de base; a soma das abas dava 6.601. Faltavam 229 peças de SKUs de cauda que as abas cortavam. Corrigido com a linha CAUDA em cada canal.
A5: Resumo era número morto | B5: As abas tinham fórmula, o Resumo era valor digitado. Mudar o crescimento não mudava o Resumo. Agora o Painel é 100% link.
A6: Faltavam canais | B6: Vitrine da loja, busca/mall e card de afiliada não existiam. Agora existem como abas, com base zero e a fonte a abrir declarada.
A7: Exato e estimado misturados | B7: Afiliada vem do extrato (exato). Live loja, vídeo loja e card vêm de split calibrado (estimado). Estavam na mesma tabela sem distinção. Agora tem coluna de confiança.
A8: Não era pace tracker | B8: Tinha "% da meta" e "falta", que em dia 3 de 31 não dizem nada. Faltava esperado-até-hoje, índice de pace, projeção de fechamento e peças/dia necessárias. Todos entraram.
A9: Meta desancorada | B9: O bottom-up dava 7.978 peças com a meta da empresa em 10.000. O relatório não mostrava esse gap. Agora ele aparece em vermelho no Painel e precisa ser fechado na aba Alavancas.
A10: Só GMV, nenhuma margem | B10: A crise é de margem, não de faturamento. Entrou contribuição por peça e contribuição-meta por SKU e por canal.
A11: Crescimento plano por canal | B11: Multiplicar todo SKU pelo mesmo percentual ignora a estratégia de portfólio. Entrou a coluna Ajuste (pç) para forçar SKU a SKU.
A12: Alavanca era rótulo de texto | B12: Rhode Squad e Copa apareciam como frase no topo da aba. Agora têm driver math na aba Alavancas e precisam somar o gap.
A13: GMV Max invisível | B13: 58% dos pedidos da loja em julho passam por ele e ele não aparecia. Entrou como sobreposição de mídia, não como canal, para não dobrar contagem.
A15: FONTE E LIMITAÇÃO DE CADA VARIÁVEL
A16: Variável | B16: Fonte | C16: É medido? | D16: Limitação
A17: Base jul — afiliada | B17: Extrato de afiliada | C17: MEDIDO | D17: Inclui concentração extrema em poucas creators.
A18: Base jul — loja | B18: Split calibrado sobre export 'Análise de produtos' | C18: INFERIDO | D18: É rateio, não leitura direta. A separação live/vídeo/card do lado vendedor é estimativa.
A19: Cauda por canal | B19: Delta entre Resumo e abas do arquivo anterior | C19: DERIVADO | D19: Sabemos o volume, não os SKUs. Preço usa média ponderada do canal.
A20: Preço plan. | B20: Preço médio realizado em julho por SKU × canal | C20: MEDIDO | D20: É preço passado usado como plano. Se houver reajuste em agosto, editar a coluna azul.
A21: CPV | B21: Modelo de unit economics travado em jul/2026 | C21: MEDIDO | D21: Blended. Não é por SKU. Wide, Mom e Baggy não custam a mesma coisa.
A22: Fee TikTok Shop | B22: — | C22: NÃO PREENCHIDO | D22: Está em 0%. Contribuição superestimada até preencher.
A23: Comissão de afiliada | B23: — | C23: NÃO PREENCHIDO | D23: Está em 0%. Canais de afiliada aparecem com contribuição maior do que a real.
A24: Devolução / cancelamento | B24: — | C24: NÃO PREENCHIDO | D24: Está em 0%. Você tem o dado aberto por SKU e tamanho — é a variável que mais muda o resultado.
A25: Real MTD (peças) | B25: Aba 'Log diário' | C25: MEDIDO | D25: Hoje é um agregado de 01–03/08 em uma linha só. A partir de amanhã, uma linha por dia.
A26: Real MTD (R$) | B26: Peças × preço médio de julho | C26: ESTIMADO | D26: GMV não foi medido no MTD. Trocar por GMV real do coletor.
A27: Esperado MTD | B27: Meta × dias decorridos ÷ dias do mês | C27: MODELO | D27: Pace linear. Ago começa em sábado e domingo, então o índice de hoje está pessimista.
... A30: Inflação de atribuição | B30: Fatia de afiliada dentro da janela de 1 dia, jul/2026 | C30: MEDIDO (PISO) | D30: É piso, não teto. O incremental real do GMV Max só sai com holdout.
A32: ROTINA DIÁRIA — o que fazer todo dia de manhã
A33: 1 | B33: Abrir 'Premissas' e mudar C6 para a data de hoje.
A34: 2 | B34: Anexar as linhas do dia anterior no fim da aba 'Log diário' — Data, Canal, SKU, Peças, GMV.
A35: 3 | B35: Abrir o Painel. Olhar só duas colunas: Índice pace e Gap vs meta.
A36: 4 | B36: Canal abaixo de 0,90x por dois dias seguidos vira ação na aba Alavancas — mexer no driver, não na meta.
A37: 5 | B37: Sexta-feira: revisar Ajuste (pç) por SKU contra estoque e grade antes de deixar a meta rodar mais uma semana.
A39: PARA O SEU AGENTE — o que ele precisa passar a entregar
A40: • | B40: Alimentar só a aba Log diário. Nunca regerar o arquivo inteiro: isso apaga os ajustes por SKU e os drivers das alavancas.
A41: • | B41: Nomes de canal têm que bater exatamente com a coluna Canal do log. Qualquer variação quebra o SUMIFS em silêncio.
A42: • | B42: Trazer GMV medido por SKU × canal, não peças × preço médio.
A43: • | B43: Trazer devolução e cancelamento por SKU no mesmo formato, para alimentar Premissas!C20.
A44: • | B44: Abrir a fonte de tráfego do lado vendedor de verdade (vitrine, busca, mall) em vez de ratear por calibração.
A45: • | B45: Reconciliar sempre: soma das abas tem que ser igual ao total. Se sobrar cauda, ela vai para a linha CAUDA, não some.

Sheet Painel
A1: PAINEL — projeção agosto/2026 por canal, com pace
A2: Tudo aqui é link para as abas de canal. Não digite nada nesta aba — edite em 'Premissas' ou na aba do canal.
A3: Atualizado para a data em Premissas!C6
A5: Canal | B5: Superfície | C5: Atribuição | D5: Confiança da base | E5: Base jul (pç) | F5: Meta (pç) | G5: Meta GMV | H5: Contrib. meta | I5: Real MTD (pç) | J5: Esperado MTD | K5: Índice pace | L5: Projeção fim (pç) | M5: Gap vs meta | N5: % da meta total
A6: Live afiliada | B6: LIVE | C6: Afiliada | D6: EXATO — extrato de afiliada | E6: ='Live afiliada'!D21 | F6: ='Live afiliada'!G21 | G6: ='Live afiliada'!I21 | H6: ='Live afiliada'!L21 | I6: ='Live afiliada'!M21 | J6: ='Live afiliada'!O21 | K6: =IFERROR(I6/J6,0) | L6: ='Live afiliada'!Q21 | M6: =L6-F6 | N6: =IFERROR(F6/$F$16,0)
A7: Vídeo afiliada | B7: VÍDEO | C7: Afiliada | D7: EXATO — extrato de afiliada | E7: ='Vídeo afiliada'!D23 | F7: ='Vídeo afiliada'!G23 | G7: ='Vídeo afiliada'!I23 | H7: ='Vídeo afiliada'!L23 | I7: ='Vídeo afiliada'!M23 | J7: ='Vídeo afiliada'!O23 | K7: =IFERROR(I7/J7,0) | L7: ='Vídeo afiliada'!Q23 | M7: =L7-F7 | N7: =IFERROR(F7/$F$16,0)
A8: Card afiliada | B8: CARD DE PRODUTO | C8: Afiliada | D8: SEM DADO — não segmentado no extrato atual | E8: ='Card afiliada'!D9 | F8: ='Card afiliada'!G9 | G8: ='Card afiliada'!I9 | H8: ='Card afiliada'!L9 | I8: ='Card afiliada'!M9 | J8: ='Card afiliada'!O9 | K8: =IFERROR(I8/J8,0) | L8: ='Card afiliada'!Q9 | M8: =L8-F8 | N8: =IFERROR(F8/$F$16,0)
A9: Live loja | B9: LIVE | C9: Loja / vendedor | D9: ESTIMADO — split calibrado, não medido | E9: ='Live loja'!D31 | F9: ='Live loja'!G31 | G9: ='Live loja'!I31 | H9: ='Live loja'!L31 | I9: ='Live loja'!M31 | J9: ='Live loja'!O31 | K9: =IFERROR(I9/J9,0) | L9: ='Live loja'!Q31 | M9: =L9-F9 | N9: =IFERROR(F9/$F$16,0)
A10: Vídeo loja | B10: VÍDEO | C10: Loja / vendedor | D10: ESTIMADO — split calibrado, não medido | E10: ='Vídeo loja'!D11 | F10: ='Vídeo loja'!G11 | G10: ='Vídeo loja'!I11 | H10: ='Vídeo loja'!L11 | I10: ='Vídeo loja'!M11 | J10: ='Vídeo loja'!O11 | K10: =IFERROR(I10/J10,0) | L10: ='Vídeo loja'!Q11 | M10: =L10-F10 | N10: =IFERROR(F10/$F$16,0)
A11: Card loja | B11: CARD DE PRODUTO | C11: Loja / vendedor | D11: ESTIMADO — split calibrado, não medido | E11: ='Card loja'!D16 | F11: ='Card loja'!G16 | G11: ='Card loja'!I16 | H11: ='Card loja'!L16 | I11: ='Card loja'!M16 | J11: ='Card loja'!O16 | K11: =IFERROR(I11/J11,0) | L11: ='Card loja'!Q16 | M11: =L11-F11 | N11: =IFERROR(F11/$F$16,0)
A12: Vitrine loja | B12: VITRINE DA LOJA | C12: Loja / vendedor | D12: SEM DADO — canal pedido, ainda não extraído | E12: ='Vitrine loja'!D9 | F12: ='Vitrine loja'!G9 | G12: ='Vitrine loja'!I9 | H12: ='Vitrine loja'!L9 | I12: ='Vitrine loja'!M9 | J12: ='Vitrine loja'!O9 | K12: =IFERROR(I12/J12,0) | L12: ='Vitrine loja'!Q9 | M12: =L12-F12 | N12: =IFERROR(F12/$F$16,0)
A13: Busca e Mall | B13: BUSCA / MALL / OUTROS | C13: Misto | D13: SEM DADO — canal pedido, ainda não extraído | E13: ='Busca e Mall'!D9 | F13: ='Busca e Mall'!G9 | G13: ='Busca e Mall'!I9 | H13: ='Busca e Mall'!L9 | I13: ='Busca e Mall'!M9 | J13: ='Busca e Mall'!O9 | K13: =IFERROR(I13/J13,0) | L13: ='Busca e Mall'!Q9 | M13: =L13-F13 | N13: =IFERROR(F13/$F$16,0)
A14: NET | E14: =SUM(E6:E13) | F14: =SUM(F6:F13) | G14: =SUM(G6:G13) | H14: =SUM(H6:H13) | I14: =SUM(I6:I13) | J14: =SUM(J6:J13) | K14: =IFERROR(I14/J14,0) | L14: =SUM(L6:L13) | M14: =SUM(M6:M13) | N14: 1
A16: RECONCILIAÇÃO COM A META DA EMPRESA
A17: Meta de peças do mês (Premissas) | B17: =Premissas!$C$13
A18: Bottom-up: soma das metas por canal | B18: =F14
A19: Gap descoberto | B19: =B17-B18
A20: Projeção pelo ritmo atual | B20: =L14
A21: Peças/dia necessárias para bater a meta da empresa | B21: =IFERROR(MAX(0,B17-I14)/Premissas!$C$9,0)
A22: Peças/dia no ritmo atual | B22: =IFERROR(I14/Premissas!$C$8,0)
A24: RISCOS E TRAVAS QUE A PROJEÇÃO NÃO CAPTURA
A25: Concentração de creator | B25: A base de julho da live afiliada carrega 1.111 peças de uma única creator no primeiro mês dela e 824 de outra. Crescer +10% em cima disso assume retenção de duas pessoas. Se uma sai, o canal cai antes de crescer.
A26: Estoque e grade | B26: Meta por SKU sem cobertura de estoque é ficção. REF516 com meta somada acima de 2.300 peças precisa de grade completa. Cancelamento por ruptura já é causa conhecida de queda.
A27: Devolução | B27: A contribuição por peça está calculada com devolução em 0% porque o dado não está neste arquivo. Você tem devolução aberta por SKU/tamanho — enquanto não entrar em Premissas!C20, toda contribuição aqui é teto, não realidade.
A28: Atribuição de mídia | B28: O GMV Max atribui pedidos que já viriam por afiliada e orgânico. O piso medido de inflação é ≥69% em REF516. Ler o ROI de mídia como incremental superestima o canal loja.
A29: Base = mês de crise | B29: Julho é o mês da queda. Crescimento percentual sobre um mês ruim entrega uma meta que ainda fica abaixo do patamar de jan–abr.

Sheet Premissas
B1: PREMISSAS — todas as variáveis editáveis do modelo
B2: Azul = você edita. Preto = fórmula. Verde = vem de outra aba. Amarelo = premissa crítica não medida, precisa ser confirmada.
B4: CALENDÁRIO
B5: Mês de referência | C5: ago/2026
B6: Data de hoje (editar todo dia) | C6: 46237
B7: Dias no mês | C7: 31
B8: Dias decorridos | C8: =DAY(C6)
B9: Dias restantes | C9: =C7-C8
B10: Fator de pace (linear) | C10: =C8/C7 | E10: Pace linear. Ago/2026 começa sáb+dom, então os 3 primeiros dias pesam MENOS que 3/31 — o índice de pace de hoje está pessimista de propósito. Trocar por curva diária quando houver histórico de dia-da-semana.
B12: META GLOBAL DO MÊS
B13: Meta de peças (editável) | C13: 10000 | E13: Meta declarada da operação.
B14: Bottom-up: soma das metas por canal | C14: =Painel!F14
B15: Gap a cobrir com alavancas | C15: =C13-C14 | E15: Este gap é o número que importa. Enquanto ele for positivo, a meta por canal NÃO fecha a meta da empresa — é preciso alavanca, não crescimento percentual.
B17: ECONÔMICO POR PEÇA
B18: CPV médio (R$/peça) | C18: 44.3 | E18: Fonte: modelo de unit economics travado em jul/2026. É blended, não por SKU.
B19: Fee TikTok Shop (%) | C19: 0 | E19: NÃO MEDIDO. Preencher com a taxa real da plataforma.
B20: Devolução + cancelamento (%) | C20: 0 | E20: NÃO MEDIDO aqui. Você tem esse dado aberto por SKU/tamanho — jogar aqui muda toda a contribuição.
B21: Contribuição/peça = | C21: preço × (1−fee) × (1−comissão) × (1−devolução) − CPV
B23: POR CANAL — crescimento e comissão
B24: Canal | C24: Crescimento vs base jul | D24: Comissão afiliada | E24: Confiança da base jul
B25: Live afiliada | C25: 0.1 | D25: 0 | E25: EXATO — extrato de afiliada
B26: Vídeo afiliada | C26: 0.3 | D26: 0 | E26: EXATO — extrato de afiliada
B27: Card afiliada | C27: 0 | D27: 0 | E27: SEM DADO — não segmentado no extrato atual
B28: Live loja | C28: 0.15 | D28: 0 | E28: ESTIMADO — split calibrado, não medido
B29: Vídeo loja | C29: 0.5 | D29: 0 | E29: ESTIMADO — split calibrado, não medido
B30: Card loja | C30: 0.2 | D30: 0 | E30: ESTIMADO — split calibrado, não medido
B31: Vitrine loja | C31: 0 | D31: 0 | E31: SEM DADO — canal pedido, ainda não extraído
B32: Busca e Mall | C32: 0 | D32: 0 | E32: SEM DADO — canal pedido, ainda não extraído
B34: Comissão de afiliada está zerada porque não foi medida. Sem ela, a contribuição dos canais de afiliada está SUPERESTIMADA.
B36: SOBREPOSIÇÃO DE MÍDIA (GMV Max) — não é canal
B37: Budget de mídia planejado (R$/mês) | C37: 40000
B38: ROI alvo | C38: 7.8
B39: Receita atribuída esperada | C39: =C37*C38
B40: Inflação de atribuição (piso medido) | C40: 0.69 | E40: Piso medido em jul/2026 (fatia de afiliada dentro da janela de 1 dia): REF516 ≥69%, REF587 ≥70%, REF588 ≥50%.
B41: Receita incremental estimada | C41: =C39*(1-C40)
B42: GMV Max atribui pedidos que já viriam por live, vídeo e card. Por isso ele NÃO entra como linha de canal no Painel — entraria em cima dos mesmos pedidos e dobraria a contagem. Ele é uma alavanca que empurra os canais existentes. O incremental real só sai com teste de holdout.

Sheet Alavancas
A1: ALAVANCAS — como o gap fecha (driver math, não percentual)
A2: Cada alavanca é medida em PEÇAS INCREMENTAIS sobre a base de julho. Edite os drivers em azul. O total precisa cobrir o gap do Painel — se não cobrir, a meta da empresa não fecha e isso fica visível aqui.
A4: Alavanca | B4: Canal alvo | C4: Driver 1 | D4: Valor | E4: Driver 2 | F4: Valor | G4: Driver 3 | H4: Valor | I4: Peças incrementais | J4: Responsável | K4: Como medir
A5: Rhode Squad | B5: Live afiliada | C5: Creators no squad | D5: 12 | E5: Lives/creator/mês | F5: 12 | G5: Peças/live | H5: 8 | I5: =ROUND(D5*F5*H5,0) | K5: Peças de live atribuídas aos creators do squad no extrato
A6: Copa Rhode Creators | B6: Vídeo afiliada | C6: Creators postando | D6: 60 | E6: Vídeos/creator/mês | F6: 6 | G6: Peças/vídeo | H6: 1.2 | I6: =ROUND(D6*F6*H6,0) | K6: Nº de creators com ≥1 peça de vídeo (base jul: 123)
A7: Desova de seeding | B7: Vídeo afiliada | C7: Amostras enviadas | D7: 120 | E7: Taxa de ativação | F7: 0.35 | G7: Peças/creator ativado | H7: 9 | I7: =ROUND(D7*F7*H7,0) | K7: Amostras enviadas × creators que postaram em 21 dias
A8: Lives próprias | B8: Live loja | C8: Sessões/mês | D8: 26 | E8: Horas/sessão | F8: 4 | G8: Peças/hora | H8: 6 | I8: =ROUND(D8*F8*H8,0) | K8: Peças da conta da loja em live
A9: Lançamento tamanho 34 | B9: Live afiliada | C9: SKUs com 34 | D9: 3 | E9: Demanda perdida/mês | F9: 400 | G9: % recuperada | H9: 0.4 | I9: =ROUND(D9*F9*H9,0) | K9: Pedidos com falha por grade antes vs depois
A10: Refresh de criativo GMV Max | B10: Espalha nos 3 | C10: Budget (R$) | D10: 40000 | E10: ROI | F10: 7.8 | G10: Preço médio | H10: 80 | I10: =ROUND(D10*F10/H10*(1-Premissas!$C$40),0) | K10: budget × ROI ÷ preço, já descontada a inflação de atribuição de Premissas!C40. CAC de criativo novo vs pool antigo — validar fora do GMV Max antes
A11: Vitrine + card organizados | B11: Vitrine loja | C11: Sessões/mês | D11: 0 | E11: CVR | F11: 0 | G11: Peças/pedido | H11: 1.1 | I11: =ROUND(D11*F11*H11,0) | K11: Depende de abrir a fonte no export — hoje não é medido
F12: GMV Max: peças = budget × ROI ÷ preço. Está aqui como alavanca, não como canal.
A13: TOTAL INCREMENTAL | I13: =SUM(I5:I11)
A15: Base julho (todos os canais) | I15: =Painel!E14
A16: Base + alavancas | I16: =I15+I13
A17: Meta da empresa | I17: =Premissas!$C$13
A18: Sobra / falta | I18: =I16-I17
A20: Cuidado com dupla contagem: a alavanca de GMV Max empurra pedidos que também aparecem em live e vídeo. Se somar tudo cru, a meta infla. Trate o número dela como teto e desconte a inflação de atribuição de Premissas!C40.

Sheet Live afiliada
A1: Live afiliada — meta por SKU e pace diário
A2: Canal (chave): | B2: Live afiliada | C2: Superfície: | D2: LIVE | F2: Atribuição: | G2: Afiliada | I2: Confiança da base jul: | K2: EXATO — extrato de afiliada
A3: Alavanca principal: | B3: Rhode Squad — squad estratégico de creators de live
A4: Crescimento vs base: | B4: =Premissas!$C$25 | C4: Comissão afiliada: | D4: =Premissas!$D$25 | F4: CPV padrão: | G4: =Premissas!$C$18
A5: Meta do canal (pç): | B5: =G21 | C5: Meta GMV: | D5: =I21 | F5: Contribuição meta: | G5: =L21 | I5: Índice de pace: | K5: =P21
A7: SKU | B7: Produto | C7: Cl | D7: Base jul (pç) | E7: Mix jul | F7: Ajuste (pç) | G7: Meta (pç) | H7: Preço plan. | I7: Meta GMV | J7: CPV | K7: Contrib./pç | L7: Contrib. meta | M7: Real MTD (pç) | N7: Real MTD (R$) | O7: Esperado MTD | P7: Índice pace | Q7: Projeção fim | R7: Gap vs meta | S7: Pç/dia p/ fechar
A8: REF516 | B8: Marmorizada | C8: H | D8: 1186 | E8: =IFERROR(D8/$D$21,0) | F8: 0 | G8: =ROUND(D8*(1+$B$4),0)+F8 | H8: 72.47 | I8: =G8*H8 | J8: =Premissas!$C$18 | K8: =H8*(1-Premissas!$C$19)*(1-$D$4)*(1-Premissas!$C$20)-J8 | L8: =G8*K8 | M8: =SUMIFS('Log diário'!$D:$D,'Log diário'!$B:$B,$B$2,'Log diário'!$C:$C,$A8) | N8: =SUMIFS('Log diário'!$E:$E,'Log diário'!$B:$B,$B$2,'Log diário'!$C:$C,$A8) | O8: =G8*Premissas!$C$10 | P8: =IFERROR(M8/O8,0) | Q8: =IFERROR(M8/Premissas!$C$8*Premissas!$C$7,0) | R8: =Q8-G8 | S8: =IFERROR(MAX(0,G8-M8)/Premissas!$C$9,0)
A9: REF525 | B9: Stone Used | C9: H | D9: 912 | E9: =IFERROR(D9/$D$21,0) | F9: 0 | G9: =ROUND(D9*(1+$B$4),0)+F9 | H9: 74.11 | I9: =G9*H9 | J9: =Premissas!$C$18 | K9: =H9*(1-Premissas!$C$19)*(1-$D$4)*(1-Premissas!$C$20)-J9 | L9: =G9*K9 | M9: =SUMIFS('Log diário'!$D:$D,'Log diário'!$B:$B,$B$2,'Log diário'!$C:$C,$A9) | N9: =SUMIFS('Log diário'!$E:$E,'Log diário'!$B:$B,$B$2,'Log diário'!$C:$C,$A9) | O9: =G9*Premissas!$C$10 | P9: =IFERROR(M9/O9,0) | Q9: =IFERROR(M9/Premissas!$C$8*Premissas!$C$7,0) | R9: =Q9-G9 | S9: =IFERROR(MAX(0,G9-M9)/Premissas!$C$9,0)
A10: REF527 | B10: Sky Used | C10: H | D10: 325 | E10: =IFERROR(D10/$D$21,0) | F10: 0 | G10: =ROUND(D10*(1+$B$4),0)+F10 | H10: 72.44 | I10: =G10*H10 | J10: =Premissas!$C$18 | K10: =H10*(1-Premissas!$C$19)*(1-$D$4)*(1-Premissas!$C$20)-J10 | L10: =G10*K10 | M10: =SUMIFS('Log diário'!$D:$D,'Log diário'!$B:$B,$B$2,'Log diário'!$C:$C,$A10) | N10: =SUMIFS('Log diário'!$E:$E,'Log diário'!$B:$B,$B$2,'Log diário'!$C:$C,$A10) | O10: =G10*Premissas!$C$10 | P10: =IFERROR(M10/O10,0) | Q10: =IFERROR(M10/Premissas!$C$8*Premissas!$C$7,0) | R10: =Q10-G10 | S10: =IFERROR(MAX(0,G10-M10)/Premissas!$C$9,0)
A11: REF562 | B11: Chocolate | C11: E | D11: 70 | E11: =IFERROR(D11/$D$21,0) | F11: 0 | G11: =ROUND(D11*(1+$B$4),0)+F11 | H11: 85.88 | I11: =G11*H11 | J11: =Premissas!$C$18 | K11: =H11*(1-Premissas!$C$19)*(1-$D$4)*(1-Premissas!$C$20)-J11 | L11: =G11*K11 | M11: =SUMIFS('Log diário'!$D:$D,'Log diário'!$B:$B,$B$2,'Log diário'!$C:$C,$A11) | N11: =SUMIFS('Log diário'!$E:$E,'Log diário'!$B:$B,$B$2,'Log diário'!$C:$C,$A11) | O11: =G11*Premissas!$C$10 | P11: =IFERROR(M11/O11,0) | Q11: =IFERROR(M11/Premissas!$C$8*Premissas!$C$7,0) | R11: =Q11-G11 | S11: =IFERROR(MAX(0,G11-M11)/Premissas!$C$9,0)
A12: REF551 | B12: Azul Médio | C12: E | D12: 46 | E12: =IFERROR(D12/$D$21,0) | F12: 0 | G12: =ROUND(D12*(1+$B$4),0)+F12 | H12: 84.51 | I12: =G12*H12 | J12: =Premissas!$C$18 | K12: =H12*(1-Premissas!$C$19)*(1-$D$4)*(1-Premissas!$C$20)-J12 | L12: =G12*K12 | M12: =SUMIFS('Log diário'!$D:$D,'Log diário'!$B:$B,$B$2,'Log diário'!$C:$C,$A12) | N12: =SUMIFS('Log diário'!$E:$E,'Log diário'!$B:$B,$B$2,'Log diário'!$C:$C,$A12) | O12: =G12*Premissas!$C$10 | P12: =IFERROR(M12/O12,0) | Q12: =IFERROR(M12/Premissas!$C$8*Premissas!$C$7,0) | R12: =Q12-G12 | S12: =IFERROR(MAX(0,G12-M12)/Premissas!$C$9,0)
A13: REF587 | B13: Baggy Marmorizada | C13: E | D13: 35 | E13: =IFERROR(D13/$D$21,0) | F13: 0 | G13: =ROUND(D13*(1+$B$4),0)+F13 | H13: 82.05 | I13: =G13*H13 | J13: =Premissas!$C$18 | K13: =H13*(1-Premissas!$C$19)*(1-$D$4)*(1-Premissas!$C$20)-J13 | L13: =G13*K13 | M13: =SUMIFS('Log diário'!$D:$D,'Log diário'!$B:$B,$B$2,'Log diário'!$C:$C,$A13) | N13: =SUMIFS('Log diário'!$E:$E,'Log diário'!$B:$B,$B$2,'Log diário'!$C:$C,$A13) | O13: =G13*Premissas!$C$10 | P13: =IFERROR(M13/O13,0) | Q13: =IFERROR(M13/Premissas!$C$8*Premissas!$C$7,0) | R13: =Q13-G13 | S13: =IFERROR(MAX(0,G13-M13)/Premissas!$C$9,0)
A14: REF528 | B14: Wide 528 | C14: E | D14: 28 | E14: =IFERROR(D14/$D$21,0) | F14: 0 | G14: =ROUND(D14*(1+$B$4),0)+F14 | H14: 79.61 | I14: =G14*H14 | J14: =Premissas!$C$18 | K14: =H14*(1-Premissas!$C$19)*(1-$D$4)*(1-Premissas!$C$20)-J14 | L14: =G14*K14 | M14: =SUMIFS('Log diário'!$D:$D,'Log diário'!$B:$B,$B$2,'Log diário'!$C:$C,$A14) | N14: =SUMIFS('Log diário'!$E:$E,'Log diário'!$B:$B,$B$2,'Log diário'!$C:$C,$A14) | O14: =G14*Premissas!$C$10 | P14: =IFERROR(M14/O14,0) | Q14: =IFERROR(M14/Premissas!$C$8*Premissas!$C$7,0) | R14: =Q14-G14 | S14: =IFERROR(MAX(0,G14-M14)/Premissas!$C$9,0)
A15: REF588 | B15: Mom Marmorizada | C15: E | D15: 22 | E15: =IFERROR(D15/$D$21,0) | F15: 0 | G15: =ROUND(D15*(1+$B$4),0)+F15 | H15: 89.24 | I15: =G15*H15 | J15: =Premissas!$C$18 | K15: =H15*(1-Premissas!$C$19)*(1-$D$4)*(1-Premissas!$C$20)-J15 | L15: =G15*K15 | M15: =SUMIFS('Log diário'!$D:$D,'Log diário'!$B:$B,$B$2,'Log diário'!$C:$C,$A15) | N15: =SUMIFS('Log diário'!$E:$E,'Log diário'!$B:$B,$B$2,'Log diário'!$C:$C,$A15) | O15: =G15*Premissas!$C$10 | P15: =IFERROR(M15/O15,0) | Q15: =IFERROR(M15/Premissas!$C$8*Premissas!$C$7,0) | R15: =Q15-G15 | S15: =IFERROR(MAX(0,G15-M15)/Premissas!$C$9,0)
A16: REF529 | B16: Wide 529 | C16: E | D16: 19 | E16: =IFERROR(D16/$D$21,0) | F16: 0 | G16: =ROUND(D16*(1+$B$4),0)+F16 | H16: 128.77 | I16: =G16*H16 | J16: =Premissas!$C$18 | K16: =H16*(1-Premissas!$C$19)*(1-$D$4)*(1-Premissas!$C$20)-J16 | L16: =G16*K16 | M16: =SUMIFS('Log diário'!$D:$D,'Log diário'!$B:$B,$B$2,'Log diário'!$C:$C,$A16) | N16: =SUMIFS('Log diário'!$E:$E,'Log diário'!$B:$B,$B$2,'Log diário'!$C:$C,$A16) | O16: =G16*Premissas!$C$10 | P16: =IFERROR(M16/O16,0) | Q16: =IFERROR(M16/Premissas!$C$8*Premissas!$C$7,0) | R16: =Q16-G16 | S16: =IFERROR(MAX(0,G16-M16)/Premissas!$C$9,0)
A17: REF549 | B17: Rosa Bebê | C17: E | D17: 13 | E17: =IFERROR(D17/$D$21,0) | F17: 0 | G17: =ROUND(D17*(1+$B$4),0)+F17 | H17: 99.68 | I17: =G17*H17 | J17: =Premissas!$C$18 | K17: =H17*(1-Premissas!$C$19)*(1-$D$4)*(1-Premissas!$C$20)-J17 | L17: =G17*K17 | M17: =SUMIFS('Log diário'!$D:$D,'Log diário'!$B:$B,$B$2,'Log diário'!$C:$C,$A17) | N17: =SUMIFS('Log diário'!$E:$E,'Log diário'!$B:$B,$B$2,'Log diário'!$C:$C,$A17) | O17: =G17*Premissas!$C$10 | P17: =IFERROR(M17/O17,0) | Q17: =IFERROR(M17/Premissas!$C$8*Premissas!$C$7,0) | R17: =Q17-G17 | S17: =IFERROR(MAX(0,G17-M17)/Premissas!$C$9,0)
A18: REF550 | B18: Amarela | C18: E | D18: 9 | E18: =IFERROR(D18/$D$21,0) | F18: 0 | G18: =ROUND(D18*(1+$B$4),0)+F18 | H18: 100.8 | I18: =G18*H18 | J18: =Premissas!$C$18 | K18: =H18*(1-Premissas!$C$19)*(1-$D$4)*(1-Premissas!$C$20)-J18 | L18: =G18*K18 | M18: =SUMIFS('Log diário'!$D:$D,'Log diário'!$B:$B,$B$2,'Log diário'!$C:$C,$A18) | N18: =SUMIFS('Log diário'!$E:$E,'Log diário'!$B:$B,$B$2,'Log diário'!$C:$C,$A18) | O18: =G18*Premissas!$C$10 | P18: =IFERROR(M18/O18,0) | Q18: =IFERROR(M18/Premissas!$C$8*Premissas!$C$7,0) | R18: =Q18-G18 | S18: =IFERROR(MAX(0,G18-M18)/Premissas!$C$9,0)
A19: REF547 | B19: (sem de-para) | C19: E | D19: 8 | E19: =IFERROR(D19/$D$21,0) | F19: 0 | G19: =ROUND(D19*(1+$B$4),0)+F19 | H19: 89.05 | I19: =G19*H19 | J19: =Premissas!$C$18 | K19: =H19*(1-Premissas!$C$19)*(1-$D$4)*(1-Premissas!$C$20)-J19 | L19: =G19*K19 | M19: =SUMIFS('Log diário'!$D:$D,'Log diário'!$B:$B,$B$2,'Log diário'!$C:$C,$A19) | N19: =SUMIFS('Log diário'!$E:$E,'Log diário'!$B:$B,$B$2,'Log diário'!$C:$C,$A19) | O19: =G19*Premissas!$C$10 | P19: =IFERROR(M19/O19,0) | Q19: =IFERROR(M19/Premissas!$C$8*Premissas!$C$7,0) | R19: =Q19-G19 | S19: =IFERROR(MAX(0,G19-M19)/Premissas!$C$9,0)
A20: CAUDA | B20: SKUs de cauda não detalhados | C20: — | D20: 32 | E20: =IFERROR(D20/$D$21,0) | F20: 0 | G20: =ROUND(D20*(1+$B$4),0)+F20 | H20: 74.6 | I20: =G20*H20 | J20: =Premissas!$C$18 | K20: =H20*(1-Premissas!$C$19)*(1-$D$4)*(1-Premissas!$C$20)-J20 | L20: =G20*K20 | M20: =SUMIFS('Log diário'!$D:$D,'Log diário'!$B:$B,$B$2,'Log diário'!$C:$C,$A20) | N20: =SUMIFS('Log diário'!$E:$E,'Log diário'!$B:$B,$B$2,'Log diário'!$C:$C,$A20) | O20: =G20*Premissas!$C$10 | P20: =IFERROR(M20/O20,0) | Q20: =IFERROR(M20/Premissas!$C$8*Premissas!$C$7,0) | R20: =Q20-G20 | S20: =IFERROR(MAX(0,G20-M20)/Premissas!$C$9,0)
A21: TOTAL | D21: =SUM(D8:D20) | E21: =SUM(E8:E20) | F21: =SUM(F8:F20) | G21: =SUM(G8:G20) | I21: =SUM(I8:I20) | L21: =SUM(L8:L20) | M21: =SUM(M8:M20) | N21: =SUM(N8:N20) | O21: =SUM(O8:O20) | P21: =IFERROR(M21/O21,0) | Q21: =SUM(Q8:Q20) | R21: =SUM(R8:R20) | S21: =SUM(S8:S20)
A22: Σ Hero | D22: =SUMIFS(D8:D20,$C$8:$C$20,"H") | G22: =SUMIFS(G8:G20,$C$8:$C$20,"H") | L22: =SUMIFS(L8:L20,$C$8:$C$20,"H")
A23: Σ Esteira | D23: =SUMIFS(D8:D20,$C$8:$C$20,"E") | G23: =SUMIFS(G8:G20,$C$8:$C$20,"E") | L23: =SUMIFS(L8:L20,$C$8:$C$20,"E")
A25: Ajuste (pç) é a coluna azul onde você força um SKU específico — lançamento do 34, pré-escala do Chocolate, abertura do Baggy. Sem ela, o modelo só escala julho de forma plana, o que contradiz a sua própria estratégia de portfólio.
A26: Índice de pace: 1,00x = exatamente no ritmo da meta. Abaixo de 1,00x = atrasado. Projeção fim = ritmo atual extrapolado até o dia 31.

Sheet Vídeo afiliada
A1: Vídeo afiliada — meta por SKU e pace diário
A2: Canal (chave): | B2: Vídeo afiliada | C2: Superfície: | D2: VÍDEO | F2: Atribuição: | G2: Afiliada | I2: Confiança da base jul: | K2: EXATO — extrato de afiliada
A3: Alavanca principal: | B3: Copa Rhode Creators (gamificação) + Academia + desova de seeding
A4: Crescimento vs base: | B4: =Premissas!$C$26 | C4: Comissão afiliada: | D4: =Premissas!$D$26 | F4: CPV padrão: | G4: =Premissas!$C$18
A5: Meta do canal (pç): | B5: =G23 | C5: Meta GMV: | D5: =I23 | F5: Contribuição meta: | G5: =L23 | I5: Índice de pace: | K5: =P23
A7: SKU | B7: Produto | C7: Cl | D7: Base jul (pç) | E7: Mix jul | F7: Ajuste (pç) | G7: Meta (pç) | H7: Preço plan. | I7: Meta GMV | J7: CPV | K7: Contrib./pç | L7: Contrib. meta | M7: Real MTD (pç) | N7: Real MTD (R$) | O7: Esperado MTD | P7: Índice pace | Q7: Projeção fim | R7: Gap vs meta | S7: Pç/dia p/ fechar
A8: REF516 | B8: Marmorizada | C8: H | D8: 715 | E8: =IFERROR(D8/$D$23,0) | F8: 0 | G8: =ROUND(D8*(1+$B$4),0)+F8 | H8: 93 | I8: =G8*H8 | J8: =Premissas!$C$18 | K8: =H8*(1-Premissas!$C$19)*(1-$D$4)*(1-Premissas!$C$20)-J8 | L8: =G8*K8 | M8: =SUMIFS('Log diário'!$D:$D,'Log diário'!$B:$B,$B$2,'Log diário'!$C:$C,$A8) | N8: =SUMIFS('Log diário'!$E:$E,'Log diário'!$B:$B,$B$2,'Log diário'!$C:$C,$A8) | O8: =G8*Premissas!$C$10 | P8: =IFERROR(M8/O8,0) | Q8: =IFERROR(M8/Premissas!$C$8*Premissas!$C$7,0) | R8: =Q8-G8 | S8: =IFERROR(MAX(0,G8-M8)/Premissas!$C$9,0)
A9: REF527 | B9: Sky Used | C9: H | D9: 183 | E9: =IFERROR(D9/$D$23,0) | F9: 0 | G9: =ROUND(D9*(1+$B$4),0)+F9 | H9: 93.74 | I9: =G9*H9 | J9: =Premissas!$C$18 | K9: =H9*(1-Premissas!$C$19)*(1-$D$4)*(1-Premissas!$C$20)-J9 | L9: =G9*K9 | M9: =SUMIFS('Log diário'!$D:$D,'Log diário'!$B:$B,$B$2,'Log diário'!$C:$C,$A9) | N9: =SUMIFS('Log diário'!$E:$E,'Log diário'!$B:$B,$B$2,'Log diário'!$C:$C,$A9) | O9: =G9*Premissas!$C$10 | P9: =IFERROR(M9/O9,0) | Q9: =IFERROR(M9/Premissas!$C$8*Premissas!$C$7,0) | R9: =Q9-G9 | S9: =IFERROR(MAX(0,G9-M9)/Premissas!$C$9,0)
A10: REF525 | B10: Stone Used | C10: H | D10: 139 | E10: =IFERROR(D10/$D$23,0) | F10: 0 | G10: =ROUND(D10*(1+$B$4),0)+F10 | H10: 98.27 | I10: =G10*H10 | J10: =Premissas!$C$18 | K10: =H10*(1-Premissas!$C$19)*(1-$D$4)*(1-Premissas!$C$20)-J10 | L10: =G10*K10 | M10: =SUMIFS('Log diário'!$D:$D,'Log diário'!$B:$B,$B$2,'Log diário'!$C:$C,$A10) | N10: =SUMIFS('Log diário'!$E:$E,'Log diário'!$B:$B,$B$2,'Log diário'!$C:$C,$A10) | O10: =G10*Premissas!$C$10 | P10: =IFERROR(M10/O10,0) | Q10: =IFERROR(M10/Premissas!$C$8*Premissas!$C$7,0) | R10: =Q10-G10 | S10: =IFERROR(MAX(0,G10-M10)/Premissas!$C$9,0)
A11: REF588 | B11: Mom Marmorizada | C11: E | D11: 127 | E11: =IFERROR(D11/$D$23,0) | F11: 0 | G11: =ROUND(D11*(1+$B$4),0)+F11 | H11: 95.76 | I11: =G11*H11 | J11: =Premissas!$C$18 | K11: =H11*(1-Premissas!$C$19)*(1-$D$4)*(1-Premissas!$C$20)-J11 | L11: =G11*K11 | M11: =SUMIFS('Log diário'!$D:$D,'Log diário'!$B:$B,$B$2,'Log diário'!$C:$C,$A11) | N11: =SUMIFS('Log diário'!$E:$E,'Log diário'!$B:$B,$B$2,'Log diário'!$C:$C,$A11) | O11: =G11*Premissas!$C$10 | P11: =IFERROR(M11/O11,0) | Q11: =IFERROR(M11/Premissas!$C$8*Premissas!$C$7,0) | R11: =Q11-G11 | S11: =IFERROR(MAX(0,G11-M11)/Premissas!$C$9,0)
A12: REF587 | B12: Baggy Marmorizada | C12: E | D12: 83 | E12: =IFERROR(D12/$D$23,0) | F12: 0 | G12: =ROUND(D12*(1+$B$4),0)+F12 | H12: 98.44 | I12: =G12*H12 | J12: =Premissas!$C$18 | K12: =H12*(1-Premissas!$C$19)*(1-$D$4)*(1-Premissas!$C$20)-J12 | L12: =G12*K12 | M12: =SUMIFS('Log diário'!$D:$D,'Log diário'!$B:$B,$B$2,'Log diário'!$C:$C,$A12) | N12: =SUMIFS('Log diário'!$E:$E,'Log diário'!$B:$B,$B$2,'Log diário'!$C:$C,$A12) | O12: =G12*Premissas!$C$10 | P12: =IFERROR(M12/O12,0) | Q12: =IFERROR(M12/Premissas!$C$8*Premissas!$C$7,0) | R12: =Q12-G12 | S12: =IFERROR(MAX(0,G12-M12)/Premissas!$C$9,0)
A13: REF549 | B13: Rosa Bebê | C13: E | D13: 45 | E13: =IFERROR(D13/$D$23,0) | F13: 0 | G13: =ROUND(D13*(1+$B$4),0)+F13 | H13: 97.23 | I13: =G13*H13 | J13: =Premissas!$C$18 | K13: =H13*(1-Premissas!$C$19)*(1-$D$4)*(1-Premissas!$C$20)-J13 | L13: =G13*K13 | M13: =SUMIFS('Log diário'!$D:$D,'Log diário'!$B:$B,$B$2,'Log diário'!$C:$C,$A13) | N13: =SUMIFS('Log diário'!$E:$E,'Log diário'!$B:$B,$B$2,'Log diário'!$C:$C,$A13) | O13: =G13*Premissas!$C$10 | P13: =IFERROR(M13/O13,0) | Q13: =IFERROR(M13/Premissas!$C$8*Premissas!$C$7,0) | R13: =Q13-G13 | S13: =IFERROR(MAX(0,G13-M13)/Premissas!$C$9,0)
A14: REF559 | B14: Mom Rosa | C14: E | D14: 26 | E14: =IFERROR(D14/$D$23,0) | F14: 0 | G14: =ROUND(D14*(1+$B$4),0)+F14 | H14: 76.3 | I14: =G14*H14 | J14: =Premissas!$C$18 | K14: =H14*(1-Premissas!$C$19)*(1-$D$4)*(1-Premissas!$C$20)-J14 | L14: =G14*K14 | M14: =SUMIFS('Log diário'!$D:$D,'Log diário'!$B:$B,$B$2,'Log diário'!$C:$C,$A14) | N14: =SUMIFS('Log diário'!$E:$E,'Log diário'!$B:$B,$B$2,'Log diário'!$C:$C,$A14) | O14: =G14*Premissas!$C$10 | P14: =IFERROR(M14/O14,0) | Q14: =IFERROR(M14/Premissas!$C$8*Premissas!$C$7,0) | R14: =Q14-G14 | S14: =IFERROR(MAX(0,G14-M14)/Premissas!$C$9,0)
A15: REF566 | B15: Mom Choco | C15: E | D15: 21 | E15: =IFERROR(D15/$D$23,0) | F15: 0 | G15: =ROUND(D15*(1+$B$4),0)+F15 | H15: 95.68 | I15: =G15*H15 | J15: =Premissas!$C$18 | K15: =H15*(1-Premissas!$C$19)*(1-$D$4)*(1-Premissas!$C$20)-J15 | L15: =G15*K15 | M15: =SUMIFS('Log diário'!$D:$D,'Log diário'!$B:$B,$B$2,'Log diário'!$C:$C,$A15) | N15: =SUMIFS('Log diário'!$E:$E,'Log diário'!$B:$B,$B$2,'Log diário'!$C:$C,$A15) | O15: =G15*Premissas!$C$10 | P15: =IFERROR(M15/O15,0) | Q15: =IFERROR(M15/Premissas!$C$8*Premissas!$C$7,0) | R15: =Q15-G15 | S15: =IFERROR(MAX(0,G15-M15)/Premissas!$C$9,0)
A16: REF558 | B16: (sem de-para) | C16: E | D16: 20 | E16: =IFERROR(D16/$D$23,0) | F16: 0 | G16: =ROUND(D16*(1+$B$4),0)+F16 | H16: 75.99 | I16: =G16*H16 | J16: =Premissas!$C$18 | K16: =H16*(1-Premissas!$C$19)*(1-$D$4)*(1-Premissas!$C$20)-J16 | L16: =G16*K16 | M16: =SUMIFS('Log diário'!$D:$D,'Log diário'!$B:$B,$B$2,'Log diário'!$C:$C,$A16) | N16: =SUMIFS('Log diário'!$E:$E,'Log diário'!$B:$B,$B$2,'Log diário'!$C:$C,$A16) | O16: =G16*Premissas!$C$10 | P16: =IFERROR(M16/O16,0) | Q16: =IFERROR(M16/Premissas!$C$8*Premissas!$C$7,0) | R16: =Q16-G16 | S16: =IFERROR(MAX(0,G16-M16)/Premissas!$C$9,0)
A17: REF562 | B17: Chocolate | C17: E | D17: 20 | E17: =IFERROR(D17/$D$23,0) | F17: 0 | G17: =ROUND(D17*(1+$B$4),0)+F17 | H17: 101.71 | I17: =G17*H17 | J17: =Premissas!$C$18 | K17: =H17*(1-Premissas!$C$19)*(1-$D$4)*(1-Premissas!$C$20)-J17 | L17: =G17*K17 | M17: =SUMIFS('Log diário'!$D:$D,'Log diário'!$B:$B,$B$2,'Log diário'!$C:$C,$A17) | N17: =SUMIFS('Log diário'!$E:$E,'Log diário'!$B:$B,$B$2,'Log diário'!$C:$C,$A17) | O17: =G17*Premissas!$C$10 | P17: =IFERROR(M17/O17,0) | Q17: =IFERROR(M17/Premissas!$C$8*Premissas!$C$7,0) | R17: =Q17-G17 | S17: =IFERROR(MAX(0,G17-M17)/Premissas!$C$9,0)
A18: REF550 | B18: Amarela | C18: E | D18: 17 | E18: =IFERROR(D18/$D$23,0) | F18: 0 | G18: =ROUND(D18*(1+$B$4),0)+F18 | H18: 101.41 | I18: =G18*H18 | J18: =Premissas!$C$18 | K18: =H18*(1-Premissas!$C$19)*(1-$D$4)*(1-Premissas!$C$20)-J18 | L18: =G18*K18 | M18: =SUMIFS('Log diário'!$D:$D,'Log diário'!$B:$B,$B$2,'Log diário'!$C:$C,$A18) | N18: =SUMIFS('Log diário'!$E:$E,'Log diário'!$B:$B,$B$2,'Log diário'!$C:$C,$A18) | O18: =G18*Premissas!$C$10 | P18: =IFERROR(M18/O18,0) | Q18: =IFERROR(M18/Premissas!$C$8*Premissas!$C$7,0) | R18: =Q18-G18 | S18: =IFERROR(MAX(0,G18-M18)/Premissas!$C$9,0)
A19: REF551 | B19: Azul Médio | C19: E | D19: 16 | E19: =IFERROR(D19/$D$23,0) | F19: 0 | G19: =ROUND(D19*(1+$B$4),0)+F19 | H19: 101.08 | I19: =G19*H19 | J19: =Premissas!$C$18 | K19: =H19*(1-Premissas!$C$19)*(1-$D$4)*(1-Premissas!$C$20)-J19 | L19: =G19*K19 | M19: =SUMIFS('Log diário'!$D:$D,'Log diário'!$B:$B,$B$2,'Log diário'!$C:$C,$A19) | N19: =SUMIFS('Log diário'!$E:$E,'Log diário'!$B:$B,$B$2,'Log diário'!$C:$C,$A19) | O19: =G19*Premissas!$C$10 | P19: =IFERROR(M19/O19,0) | Q19: =IFERROR(M19/Premissas!$C$8*Premissas!$C$7,0) | R19: =Q19-G19 | S19: =IFERROR(MAX(0,G19-M19)/Premissas!$C$9,0)
... A22: CAUDA | B22: SKUs de cauda não detalhados | C22: — | D22: 39 | E22: =IFERROR(D22/$D$23,0) | F22: 0 | G22: =ROUND(D22*(1+$B$4),0)+F22 | H22: 94.16 | I22: =G22*H22 | J22: =Premissas!$C$18 | K22: =H22*(1-Premissas!$C$19)*(1-$D$4)*(1-Premissas!$C$20)-J22 | L22: =G22*K22 | M22: =SUMIFS('Log diário'!$D:$D,'Log diário'!$B:$B,$B$2,'Log diário'!$C:$C,$A22) | N22: =SUMIFS('Log diário'!$E:$E,'Log diário'!$B:$B,$B$2,'Log diário'!$C:$C,$A22) | O22: =G22*Premissas!$C$10 | P22: =IFERROR(M22/O22,0) | Q22: =IFERROR(M22/Premissas!$C$8*Premissas!$C$7,0) | R22: =Q22-G22 | S22: =IFERROR(MAX(0,G22-M22)/Premissas!$C$9,0)
A23: TOTAL | D23: =SUM(D8:D22) | E23: =SUM(E8:E22) | F23: =SUM(F8:F22) | G23: =SUM(G8:G22) | I23: =SUM(I8:I22) | L23: =SUM(L8:L22) | M23: =SUM(M8:M22) | N23: =SUM(N8:N22) | O23: =SUM(O8:O22) | P23: =IFERROR(M23/O23,0) | Q23: =SUM(Q8:Q22) | R23: =SUM(R8:R22) | S23: =SUM(S8:S22)
A24: Σ Hero | D24: =SUMIFS(D8:D22,$C$8:$C$22,"H") | G24: =SUMIFS(G8:G22,$C$8:$C$22,"H") | L24: =SUMIFS(L8:L22,$C$8:$C$22,"H")
A25: Σ Esteira | D25: =SUMIFS(D8:D22,$C$8:$C$22,"E") | G25: =SUMIFS(G8:G22,$C$8:$C$22,"E") | L25: =SUMIFS(L8:L22,$C$8:$C$22,"E")
A27: Ajuste (pç) é a coluna azul onde você força um SKU específico — lançamento do 34, pré-escala do Chocolate, abertura do Baggy. Sem ela, o modelo só escala julho de forma plana, o que contradiz a sua própria estratégia de portfólio.
A28: Índice de pace: 1,00x = exatamente no ritmo da meta. Abaixo de 1,00x = atrasado. Projeção fim = ritmo atual extrapolado até o dia 31.

Sheet Card afiliada
A1: Card afiliada — meta por SKU e pace diário
A2: Canal (chave): | B2: Card afiliada | C2: Superfície: | D2: CARD DE PRODUTO | F2: Atribuição: | G2: Afiliada | I2: Confiança da base jul: | K2: EXATO — afiliada showcase/card (SHOP+LINKSHARE) do extrato. ~1,5% do GMV.
A3: Alavanca principal: | B3: A definir — depende de abrir a fonte no extrato de afiliada
A4: Crescimento vs base: | B4: =Premissas!$C$27 | C4: Comissão afiliada: | D4: =Premissas!$D$27 | F4: CPV padrão: | G4: =Premissas!$C$18
A5: Meta do canal (pç): | B5: =G9 | C5: Meta GMV: | D5: =I9 | F5: Contribuição meta: | G5: =L9 | I5: Índice de pace: | K5: =P9
A7: SKU | B7: Produto | C7: Cl | D7: Base jul (pç) | E7: Mix jul | F7: Ajuste (pç) | G7: Meta (pç) | H7: Preço plan. | I7: Meta GMV | J7: CPV | K7: Contrib./pç | L7: Contrib. meta | M7: Real MTD (pç) | N7: Real MTD (R$) | O7: Esperado MTD | P7: Índice pace | Q7: Projeção fim | R7: Gap vs meta | S7: Pç/dia p/ fechar
A8: AGREGADO | B8: Afiliada showcase/card (SHOP+LINKSHARE) | C8: E | D8: 75 | E8: =IFERROR(D8/$D$9,0) | F8: 0 | G8: =ROUND(D8*(1+$B$4),0)+F8 | H8: 94.98 | I8: =G8*H8 | J8: =Premissas!$C$18 | K8: =H8*(1-Premissas!$C$19)*(1-$D$4)*(1-Premissas!$C$20)-J8 | L8: =G8*K8 | M8: =SUMIFS('Log diário'!$D:$D,'Log diário'!$B:$B,$B$2,'Log diário'!$C:$C,$A8) | N8: =SUMIFS('Log diário'!$E:$E,'Log diário'!$B:$B,$B$2,'Log diário'!$C:$C,$A8) | O8: =G8*Premissas!$C$10 | P8: =IFERROR(M8/O8,0) | Q8: =IFERROR(M8/Premissas!$C$8*Premissas!$C$7,0) | R8: =Q8-G8 | S8: =IFERROR(MAX(0,G8-M8)/Premissas!$C$9,0)
A9: TOTAL | D9: =SUM(D8:D8) | E9: =SUM(E8:E8) | F9: =SUM(F8:F8) | G9: =SUM(G8:G8) | I9: =SUM(I8:I8) | L9: =SUM(L8:L8) | M9: =SUM(M8:M8) | N9: =SUM(N8:N8) | O9: =SUM(O8:O8) | P9: =IFERROR(M9/O9,0) | Q9: =SUM(Q8:Q8) | R9: =SUM(R8:R8) | S9: =SUM(S8:S8)
A10: Σ Hero | D10: =SUMIFS(D8:D8,$C$8:$C$8,"H") | G10: =SUMIFS(G8:G8,$C$8:$C$8,"H") | L10: =SUMIFS(L8:L8,$C$8:$C$8,"H")
A11: Σ Esteira | D11: =SUMIFS(D8:D8,$C$8:$C$8,"E") | G11: =SUMIFS(G8:G8,$C$8:$C$8,"E") | L11: =SUMIFS(L8:L8,$C$8:$C$8,"E")
A13: Ajuste (pç) é a coluna azul onde você força um SKU específico — lançamento do 34, pré-escala do Chocolate, abertura do Baggy. Sem ela, o modelo só escala julho de forma plana, o que contradiz a sua própria estratégia de portfólio.
A14: Índice de pace: 1,00x = exatamente no ritmo da meta. Abaixo de 1,00x = atrasado. Projeção fim = ritmo atual extrapolado até o dia 31.

Sheet Live loja
A1: Live loja — meta por SKU e pace diário
A2: Canal (chave): | B2: Live loja | C2: Superfície: | D2: LIVE | F2: Atribuição: | G2: Loja / vendedor | I2: Confiança da base jul: | K2: ESTIMADO — split calibrado, não medido
A3: Alavanca principal: | B3: Escalar sessões próprias + restaurar mídia de live
A4: Crescimento vs base: | B4: =Premissas!$C$28 | C4: Comissão afiliada: | D4: =Premissas!$D$28 | F4: CPV padrão: | G4: =Premissas!$C$18
A5: Meta do canal (pç): | B5: =G31 | C5: Meta GMV: | D5: =I31 | F5: Contribuição meta: | G5: =L31 | I5: Índice de pace: | K5: =P31
A7: SKU | B7: Produto | C7: Cl | D7: Base jul (pç) | E7: Mix jul | F7: Ajuste (pç) | G7: Meta (pç) | H7: Preço plan. | I7: Meta GMV | J7: CPV | K7: Contrib./pç | L7: Contrib. meta | M7: Real MTD (pç) | N7: Real MTD (R$) | O7: Esperado MTD | P7: Índice pace | Q7: Projeção fim | R7: Gap vs meta | S7: Pç/dia p/ fechar
A8: REF516 | B8: Marmorizada | C8: H | D8: 824 | E8: =IFERROR(D8/$D$31,0) | F8: 0 | G8: =ROUND(D8*(1+$B$4),0)+F8 | H8: 73.05 | I8: =G8*H8 | J8: =Premissas!$C$18 | K8: =H8*(1-Premissas!$C$19)*(1-$D$4)*(1-Premissas!$C$20)-J8 | L8: =G8*K8 | M8: =SUMIFS('Log diário'!$D:$D,'Log diário'!$B:$B,$B$2,'Log diário'!$C:$C,$A8) | N8: =SUMIFS('Log diário'!$E:$E,'Log diário'!$B:$B,$B$2,'Log diário'!$C:$C,$A8) | O8: =G8*Premissas!$C$10 | P8: =IFERROR(M8/O8,0) | Q8: =IFERROR(M8/Premissas!$C$8*Premissas!$C$7,0) | R8: =Q8-G8 | S8: =IFERROR(MAX(0,G8-M8)/Premissas!$C$9,0)
A9: REF525 | B9: Stone Used | C9: H | D9: 319 | E9: =IFERROR(D9/$D$31,0) | F9: 0 | G9: =ROUND(D9*(1+$B$4),0)+F9 | H9: 73.45 | I9: =G9*H9 | J9: =Premissas!$C$18 | K9: =H9*(1-Premissas!$C$19)*(1-$D$4)*(1-Premissas!$C$20)-J9 | L9: =G9*K9 | M9: =SUMIFS('Log diário'!$D:$D,'Log diário'!$B:$B,$B$2,'Log diário'!$C:$C,$A9) | N9: =SUMIFS('Log diário'!$E:$E,'Log diário'!$B:$B,$B$2,'Log diário'!$C:$C,$A9) | O9: =G9*Premissas!$C$10 | P9: =IFERROR(M9/O9,0) | Q9: =IFERROR(M9/Premissas!$C$8*Premissas!$C$7,0) | R9: =Q9-G9 | S9: =IFERROR(MAX(0,G9-M9)/Premissas!$C$9,0)
A10: REF527 | B10: Sky Used | C10: H | D10: 238 | E10: =IFERROR(D10/$D$31,0) | F10: 0 | G10: =ROUND(D10*(1+$B$4),0)+F10 | H10: 72.79 | I10: =G10*H10 | J10: =Premissas!$C$18 | K10: =H10*(1-Premissas!$C$19)*(1-$D$4)*(1-Premissas!$C$20)-J10 | L10: =G10*K10 | M10: =SUMIFS('Log diário'!$D:$D,'Log diário'!$B:$B,$B$2,'Log diário'!$C:$C,$A10) | N10: =SUMIFS('Log diário'!$E:$E,'Log diário'!$B:$B,$B$2,'Log diário'!$C:$C,$A10) | O10: =G10*Premissas!$C$10 | P10: =IFERROR(M10/O10,0) | Q10: =IFERROR(M10/Premissas!$C$8*Premissas!$C$7,0) | R10: =Q10-G10 | S10: =IFERROR(MAX(0,G10-M10)/Premissas!$C$9,0)
A11: REF551 | B11: Azul Médio | C11: E | D11: 156 | E11: =IFERROR(D11/$D$31,0) | F11: 0 | G11: =ROUND(D11*(1+$B$4),0)+F11 | H11: 85.11 | I11: =G11*H11 | J11: =Premissas!$C$18 | K11: =H11*(1-Premissas!$C$19)*(1-$D$4)*(1-Premissas!$C$20)-J11 | L11: =G11*K11 | M11: =SUMIFS('Log diário'!$D:$D,'Log diário'!$B:$B,$B$2,'Log diário'!$C:$C,$A11) | N11: =SUMIFS('Log diário'!$E:$E,'Log diário'!$B:$B,$B$2,'Log diário'!$C:$C,$A11) | O11: =G11*Premissas!$C$10 | P11: =IFERROR(M11/O11,0) | Q11: =IFERROR(M11/Premissas!$C$8*Premissas!$C$7,0) | R11: =Q11-G11 | S11: =IFERROR(MAX(0,G11-M11)/Premissas!$C$9,0)
A12: REF588 | B12: Mom Marmorizada | C12: E | D12: 136 | E12: =IFERROR(D12/$D$31,0) | F12: 0 | G12: =ROUND(D12*(1+$B$4),0)+F12 | H12: 85.13 | I12: =G12*H12 | J12: =Premissas!$C$18 | K12: =H12*(1-Premissas!$C$19)*(1-$D$4)*(1-Premissas!$C$20)-J12 | L12: =G12*K12 | M12: =SUMIFS('Log diário'!$D:$D,'Log diário'!$B:$B,$B$2,'Log diário'!$C:$C,$A12) | N12: =SUMIFS('Log diário'!$E:$E,'Log diário'!$B:$B,$B$2,'Log diário'!$C:$C,$A12) | O12: =G12*Premissas!$C$10 | P12: =IFERROR(M12/O12,0) | Q12: =IFERROR(M12/Premissas!$C$8*Premissas!$C$7,0) | R12: =Q12-G12 | S12: =IFERROR(MAX(0,G12-M12)/Premissas!$C$9,0)
A13: REF528 | B13: Wide 528 | C13: E | D13: 135 | E13: =IFERROR(D13/$D$31,0) | F13: 0 | G13: =ROUND(D13*(1+$B$4),0)+F13 | H13: 80.48 | I13: =G13*H13 | J13: =Premissas!$C$18 | K13: =H13*(1-Premissas!$C$19)*(1-$D$4)*(1-Premissas!$C$20)-J13 | L13: =G13*K13 | M13: =SUMIFS('Log diário'!$D:$D,'Log diário'!$B:$B,$B$2,'Log diário'!$C:$C,$A13) | N13: =SUMIFS('Log diário'!$E:$E,'Log diário'!$B:$B,$B$2,'Log diário'!$C:$C,$A13) | O13: =G13*Premissas!$C$10 | P13: =IFERROR(M13/O13,0) | Q13: =IFERROR(M13/Premissas!$C$8*Premissas!$C$7,0) | R13: =Q13-G13 | S13: =IFERROR(MAX(0,G13-M13)/Premissas!$C$9,0)
A14: REF562 | B14: Chocolate | C14: E | D14: 86 | E14: =IFERROR(D14/$D$31,0) | F14: 0 | G14: =ROUND(D14*(1+$B$4),0)+F14 | H14: 85.63 | I14: =G14*H14 | J14: =Premissas!$C$18 | K14: =H14*(1-Premissas!$C$19)*(1-$D$4)*(1-Premissas!$C$20)-J14 | L14: =G14*K14 | M14: =SUMIFS('Log diário'!$D:$D,'Log diário'!$B:$B,$B$2,'Log diário'!$C:$C,$A14) | N14: =SUMIFS('Log diário'!$E:$E,'Log diário'!$B:$B,$B$2,'Log diário'!$C:$C,$A14) | O14: =G14*Premissas!$C$10 | P14: =IFERROR(M14/O14,0) | Q14: =IFERROR(M14/Premissas!$C$8*Premissas!$C$7,0) | R14: =Q14-G14 | S14: =IFERROR(MAX(0,G14-M14)/Premissas!$C$9,0)
A15: REF587 | B15: Baggy Marmorizada | C15: E | D15: 51 | E15: =IFERROR(D15/$D$31,0) | F15: 0 | G15: =ROUND(D15*(1+$B$4),0)+F15 | H15: 75.73 | I15: =G15*H15 | J15: =Premissas!$C$18 | K15: =H15*(1-Premissas!$C$19)*(1-$D$4)*(1-Premissas!$C$20)-J15 | L15: =G15*K15 | M15: =SUMIFS('Log diário'!$D:$D,'Log diário'!$B:$B,$B$2,'Log diário'!$C:$C,$A15) | N15: =SUMIFS('Log diário'!$E:$E,'Log diário'!$B:$B,$B$2,'Log diário'!$C:$C,$A15) | O15: =G15*Premissas!$C$10 | P15: =IFERROR(M15/O15,0) | Q15: =IFERROR(M15/Premissas!$C$8*Premissas!$C$7,0) | R15: =Q15-G15 | S15: =IFERROR(MAX(0,G15-M15)/Premissas!$C$9,0)
A16: REF547 | B16: (sem de-para) | C16: E | D16: 51 | E16: =IFERROR(D16/$D$31,0) | F16: 0 | G16: =ROUND(D16*(1+$B$4),0)+F16 | H16: 84.83 | I16: =G16*H16 | J16: =Premissas!$C$18 | K16: =H16*(1-Premissas!$C$19)*(1-$D$4)*(1-Premissas!$C$20)-J16 | L16: =G16*K16 | M16: =SUMIFS('Log diário'!$D:$D,'Log diário'!$B:$B,$B$2,'Log diário'!$C:$C,$A16) | N16: =SUMIFS('Log diário'!$E:$E,'Log diário'!$B:$B,$B$2,'Log diário'!$C:$C,$A16) | O16: =G16*Premissas!$C$10 | P16: =IFERROR(M16/O16,0) | Q16: =IFERROR(M16/Premissas!$C$8*Premissas!$C$7,0) | R16: =Q16-G16 | S16: =IFERROR(MAX(0,G16-M16)/Premissas!$C$9,0)
A17: REF529 | B17: Wide 529 | C17: E | D17: 45 | E17: =IFERROR(D17/$D$31,0) | F17: 0 | G17: =ROUND(D17*(1+$B$4),0)+F17 | H17: 111.23 | I17: =G17*H17 | J17: =Premissas!$C$18 | K17: =H17*(1-Premissas!$C$19)*(1-$D$4)*(1-Premissas!$C$20)-J17 | L17: =G17*K17 | M17: =SUMIFS('Log diário'!$D:$D,'Log diário'!$B:$B,$B$2,'Log diário'!$C:$C,$A17) | N17: =SUMIFS('Log diário'!$E:$E,'Log diário'!$B:$B,$B$2,'Log diário'!$C:$C,$A17) | O17: =G17*Premissas!$C$10 | P17: =IFERROR(M17/O17,0) | Q17: =IFERROR(M17/Premissas!$C$8*Premissas!$C$7,0) | R17: =Q17-G17 | S17: =IFERROR(MAX(0,G17-M17)/Premissas!$C$9,0)
A18: REF549 | B18: Rosa Bebê | C18: E | D18: 31 | E18: =IFERROR(D18/$D$31,0) | F18: 0 | G18: =ROUND(D18*(1+$B$4),0)+F18 | H18: 87.72 | I18: =G18*H18 | J18: =Premissas!$C$18 | K18: =H18*(1-Premissas!$C$19)*(1-$D$4)*(1-Premissas!$C$20)-J18 | L18: =G18*K18 | M18: =SUMIFS('Log diário'!$D:$D,'Log diário'!$B:$B,$B$2,'Log diário'!$C:$C,$A18) | N18: =SUMIFS('Log diário'!$E:$E,'Log diário'!$B:$B,$B$2,'Log diário'!$C:$C,$A18) | O18: =G18*Premissas!$C$10 | P18: =IFERROR(M18/O18,0) | Q18: =IFERROR(M18/Premissas!$C$8*Premissas!$C$7,0) | R18: =Q18-G18 | S18: =IFERROR(MAX(0,G18-M18)/Premissas!$C$9,0)
A19: REF546 | B19: (sem de-para) | C19: E | D19: 27 | E19: =IFERROR(D19/$D$31,0) | F19: 0 | G19: =ROUND(D19*(1+$B$4),0)+F19 | H19: 89.95 | I19: =G19*H19 | J19: =Premissas!$C$18 | K19: =H19*(1-Premissas!$C$19)*(1-$D$4)*(1-Premissas!$C$20)-J19 | L19: =G19*K19 | M19: =SUMIFS('Log diário'!$D:$D,'Log diário'!$B:$B,$B$2,'Log diário'!$C:$C,$A19) | N19: =SUMIFS('Log diário'!$E:$E,'Log diário'!$B:$B,$B$2,'Log diário'!$C:$C,$A19) | O19: =G19*Premissas!$C$10 | P19: =IFERROR(M19/O19,0) | Q19: =IFERROR(M19/Premissas!$C$8*Premissas!$C$7,0) | R19: =Q19-G19 | S19: =IFERROR(MAX(0,G19-M19)/Premissas!$C$9,0)
... A30: CAUDA | B30: SKUs de cauda não detalhados | C30: — | D30: 78 | E30: =IFERROR(D30/$D$31,0) | F30: 0 | G30: =ROUND(D30*(1+$B$4),0)+F30 | H30: 76.35 | I30: =G30*H30 | J30: =Premissas!$C$18 | K30: =H30*(1-Premissas!$C$19)*(1-$D$4)*(1-Premissas!$C$20)-J30 | L30: =G30*K30 | M30: =SUMIFS('Log diário'!$D:$D,'Log diário'!$B:$B,$B$2,'Log diário'!$C:$C,$A30) | N30: =SUMIFS('Log diário'!$E:$E,'Log diário'!$B:$B,$B$2,'Log diário'!$C:$C,$A30) | O30: =G30*Premissas!$C$10 | P30: =IFERROR(M30/O30,0) | Q30: =IFERROR(M30/Premissas!$C$8*Premissas!$C$7,0) | R30: =Q30-G30 | S30: =IFERROR(MAX(0,G30-M30)/Premissas!$C$9,0)
A31: TOTAL | D31: =SUM(D8:D30) | E31: =SUM(E8:E30) | F31: =SUM(F8:F30) | G31: =SUM(G8:G30) | I31: =SUM(I8:I30) | L31: =SUM(L8:L30) | M31: =SUM(M8:M30) | N31: =SUM(N8:N30) | O31: =SUM(O8:O30) | P31: =IFERROR(M31/O31,0) | Q31: =SUM(Q8:Q30) | R31: =SUM(R8:R30) | S31: =SUM(S8:S30)
A32: Σ Hero | D32: =SUMIFS(D8:D30,$C$8:$C$30,"H") | G32: =SUMIFS(G8:G30,$C$8:$C$30,"H") | L32: =SUMIFS(L8:L30,$C$8:$C$30,"H")
A33: Σ Esteira | D33: =SUMIFS(D8:D30,$C$8:$C$30,"E") | G33: =SUMIFS(G8:G30,$C$8:$C$30,"E") | L33: =SUMIFS(L8:L30,$C$8:$C$30,"E")
A35: Ajuste (pç) é a coluna azul onde você força um SKU específico — lançamento do 34, pré-escala do Chocolate, abertura do Baggy. Sem ela, o modelo só escala julho de forma plana, o que contradiz a sua própria estratégia de portfólio.
A36: Índice de pace: 1,00x = exatamente no ritmo da meta. Abaixo de 1,00x = atrasado. Projeção fim = ritmo atual extrapolado até o dia 31.

Sheet Vídeo loja
A1: Vídeo loja — meta por SKU e pace diário
A2: Canal (chave): | B2: Vídeo loja | C2: Superfície: | D2: VÍDEO | F2: Atribuição: | G2: Loja / vendedor | I2: Confiança da base jul: | K2: ESTIMADO — split calibrado, não medido
A3: Alavanca principal: | B3: Residual — vídeo próprio do seller (quase zero hoje)
A4: Crescimento vs base: | B4: =Premissas!$C$29 | C4: Comissão afiliada: | D4: =Premissas!$D$29 | F4: CPV padrão: | G4: =Premissas!$C$18
A5: Meta do canal (pç): | B5: =G11 | C5: Meta GMV: | D5: =I11 | F5: Contribuição meta: | G5: =L11 | I5: Índice de pace: | K5: =P11
A7: SKU | B7: Produto | C7: Cl | D7: Base jul (pç) | E7: Mix jul | F7: Ajuste (pç) | G7: Meta (pç) | H7: Preço plan. | I7: Meta GMV | J7: CPV | K7: Contrib./pç | L7: Contrib. meta | M7: Real MTD (pç) | N7: Real MTD (R$) | O7: Esperado MTD | P7: Índice pace | Q7: Projeção fim | R7: Gap vs meta | S7: Pç/dia p/ fechar
A8: REF516 | B8: Marmorizada | C8: H | D8: 24 | E8: =IFERROR(D8/$D$11,0) | F8: 0 | G8: =ROUND(D8*(1+$B$4),0)+F8 | H8: 73.05 | I8: =G8*H8 | J8: =Premissas!$C$18 | K8: =H8*(1-Premissas!$C$19)*(1-$D$4)*(1-Premissas!$C$20)-J8 | L8: =G8*K8 | M8: =SUMIFS('Log diário'!$D:$D,'Log diário'!$B:$B,$B$2,'Log diário'!$C:$C,$A8) | N8: =SUMIFS('Log diário'!$E:$E,'Log diário'!$B:$B,$B$2,'Log diário'!$C:$C,$A8) | O8: =G8*Premissas!$C$10 | P8: =IFERROR(M8/O8,0) | Q8: =IFERROR(M8/Premissas!$C$8*Premissas!$C$7,0) | R8: =Q8-G8 | S8: =IFERROR(MAX(0,G8-M8)/Premissas!$C$9,0)
A9: REF525 | B9: Stone Used | C9: H | D9: 9 | E9: =IFERROR(D9/$D$11,0) | F9: 0 | G9: =ROUND(D9*(1+$B$4),0)+F9 | H9: 73.45 | I9: =G9*H9 | J9: =Premissas!$C$18 | K9: =H9*(1-Premissas!$C$19)*(1-$D$4)*(1-Premissas!$C$20)-J9 | L9: =G9*K9 | M9: =SUMIFS('Log diário'!$D:$D,'Log diário'!$B:$B,$B$2,'Log diário'!$C:$C,$A9) | N9: =SUMIFS('Log diário'!$E:$E,'Log diário'!$B:$B,$B$2,'Log diário'!$C:$C,$A9) | O9: =G9*Premissas!$C$10 | P9: =IFERROR(M9/O9,0) | Q9: =IFERROR(M9/Premissas!$C$8*Premissas!$C$7,0) | R9: =Q9-G9 | S9: =IFERROR(MAX(0,G9-M9)/Premissas!$C$9,0)
A10: CAUDA | B10: SKUs de cauda não detalhados | C10: — | D10: 34 | E10: =IFERROR(D10/$D$11,0) | F10: 0 | G10: =ROUND(D10*(1+$B$4),0)+F10 | H10: 73.16 | I10: =G10*H10 | J10: =Premissas!$C$18 | K10: =H10*(1-Premissas!$C$19)*(1-$D$4)*(1-Premissas!$C$20)-J10 | L10: =G10*K10 | M10: =SUMIFS('Log diário'!$D:$D,'Log diário'!$B:$B,$B$2,'Log diário'!$C:$C,$A10) | N10: =SUMIFS('Log diário'!$E:$E,'Log diário'!$B:$B,$B$2,'Log diário'!$C:$C,$A10) | O10: =G10*Premissas!$C$10 | P10: =IFERROR(M10/O10,0) | Q10: =IFERROR(M10/Premissas!$C$8*Premissas!$C$7,0) | R10: =Q10-G10 | S10: =IFERROR(MAX(0,G10-M10)/Premissas!$C$9,0)
A11: TOTAL | D11: =SUM(D8:D10) | E11: =SUM(E8:E10) | F11: =SUM(F8:F10) | G11: =SUM(G8:G10) | I11: =SUM(I8:I10) | L11: =SUM(L8:L10) | M11: =SUM(M8:M10) | N11: =SUM(N8:N10) | O11: =SUM(O8:O10) | P11: =IFERROR(M11/O11,0) | Q11: =SUM(Q8:Q10) | R11: =SUM(R8:R10) | S11: =SUM(S8:S10)
A12: Σ Hero | D12: =SUMIFS(D8:D10,$C$8:$C$10,"H") | G12: =SUMIFS(G8:G10,$C$8:$C$10,"H") | L12: =SUMIFS(L8:L10,$C$8:$C$10,"H")
A13: Σ Esteira | D13: =SUMIFS(D8:D10,$C$8:$C$10,"E") | G13: =SUMIFS(G8:G10,$C$8:$C$10,"E") | L13: =SUMIFS(L8:L10,$C$8:$C$10,"E")
A15: Ajuste (pç) é a coluna azul onde você força um SKU específico — lançamento do 34, pré-escala do Chocolate, abertura do Baggy. Sem ela, o modelo só escala julho de forma plana, o que contradiz a sua própria estratégia de portfólio.
A16: Índice de pace: 1,00x = exatamente no ritmo da meta. Abaixo de 1,00x = atrasado. Projeção fim = ritmo atual extrapolado até o dia 31.

Sheet Card loja
A1: Card loja — meta por SKU e pace diário
A2: Canal (chave): | B2: Card loja | C2: Superfície: | D2: CARD DE PRODUTO | F2: Atribuição: | G2: Loja / vendedor | I2: Confiança da base jul: | K2: ESTIMADO — split calibrado, não medido
A3: Alavanca principal: | B3: Holdout do card → então reabrir mídia
A4: Crescimento vs base: | B4: =Premissas!$C$30 | C4: Comissão afiliada: | D4: =Premissas!$D$30 | F4: CPV padrão: | G4: =Premissas!$C$18
A5: Meta do canal (pç): | B5: =G16 | C5: Meta GMV: | D5: =I16 | F5: Contribuição meta: | G5: =L16 | I5: Índice de pace: | K5: =P16
A7: SKU | B7: Produto | C7: Cl | D7: Base jul (pç) | E7: Mix jul | F7: Ajuste (pç) | G7: Meta (pç) | H7: Preço plan. | I7: Meta GMV | J7: CPV | K7: Contrib./pç | L7: Contrib. meta | M7: Real MTD (pç) | N7: Real MTD (R$) | O7: Esperado MTD | P7: Índice pace | Q7: Projeção fim | R7: Gap vs meta | S7: Pç/dia p/ fechar
A8: REF516 | B8: Marmorizada | C8: H | D8: 89 | E8: =IFERROR(D8/$D$16,0) | F8: 0 | G8: =ROUND(D8*(1+$B$4),0)+F8 | H8: 73.05 | I8: =G8*H8 | J8: =Premissas!$C$18 | K8: =H8*(1-Premissas!$C$19)*(1-$D$4)*(1-Premissas!$C$20)-J8 | L8: =G8*K8 | M8: =SUMIFS('Log diário'!$D:$D,'Log diário'!$B:$B,$B$2,'Log diário'!$C:$C,$A8) | N8: =SUMIFS('Log diário'!$E:$E,'Log diário'!$B:$B,$B$2,'Log diário'!$C:$C,$A8) | O8: =G8*Premissas!$C$10 | P8: =IFERROR(M8/O8,0) | Q8: =IFERROR(M8/Premissas!$C$8*Premissas!$C$7,0) | R8: =Q8-G8 | S8: =IFERROR(MAX(0,G8-M8)/Premissas!$C$9,0)
A9: REF525 | B9: Stone Used | C9: H | D9: 35 | E9: =IFERROR(D9/$D$16,0) | F9: 0 | G9: =ROUND(D9*(1+$B$4),0)+F9 | H9: 73.45 | I9: =G9*H9 | J9: =Premissas!$C$18 | K9: =H9*(1-Premissas!$C$19)*(1-$D$4)*(1-Premissas!$C$20)-J9 | L9: =G9*K9 | M9: =SUMIFS('Log diário'!$D:$D,'Log diário'!$B:$B,$B$2,'Log diário'!$C:$C,$A9) | N9: =SUMIFS('Log diário'!$E:$E,'Log diário'!$B:$B,$B$2,'Log diário'!$C:$C,$A9) | O9: =G9*Premissas!$C$10 | P9: =IFERROR(M9/O9,0) | Q9: =IFERROR(M9/Premissas!$C$8*Premissas!$C$7,0) | R9: =Q9-G9 | S9: =IFERROR(MAX(0,G9-M9)/Premissas!$C$9,0)
A10: REF527 | B10: Sky Used | C10: H | D10: 26 | E10: =IFERROR(D10/$D$16,0) | F10: 0 | G10: =ROUND(D10*(1+$B$4),0)+F10 | H10: 72.79 | I10: =G10*H10 | J10: =Premissas!$C$18 | K10: =H10*(1-Premissas!$C$19)*(1-$D$4)*(1-Premissas!$C$20)-J10 | L10: =G10*K10 | M10: =SUMIFS('Log diário'!$D:$D,'Log diário'!$B:$B,$B$2,'Log diário'!$C:$C,$A10) | N10: =SUMIFS('Log diário'!$E:$E,'Log diário'!$B:$B,$B$2,'Log diário'!$C:$C,$A10) | O10: =G10*Premissas!$C$10 | P10: =IFERROR(M10/O10,0) | Q10: =IFERROR(M10/Premissas!$C$8*Premissas!$C$7,0) | R10: =Q10-G10 | S10: =IFERROR(MAX(0,G10-M10)/Premissas!$C$9,0)
A11: REF551 | B11: Azul Médio | C11: E | D11: 17 | E11: =IFERROR(D11/$D$16,0) | F11: 0 | G11: =ROUND(D11*(1+$B$4),0)+F11 | H11: 85.11 | I11: =G11*H11 | J11: =Premissas!$C$18 | K11: =H11*(1-Premissas!$C$19)*(1-$D$4)*(1-Premissas!$C$20)-J11 | L11: =G11*K11 | M11: =SUMIFS('Log diário'!$D:$D,'Log diário'!$B:$B,$B$2,'Log diário'!$C:$C,$A11) | N11: =SUMIFS('Log diário'!$E:$E,'Log diário'!$B:$B,$B$2,'Log diário'!$C:$C,$A11) | O11: =G11*Premissas!$C$10 | P11: =IFERROR(M11/O11,0) | Q11: =IFERROR(M11/Premissas!$C$8*Premissas!$C$7,0) | R11: =Q11-G11 | S11: =IFERROR(MAX(0,G11-M11)/Premissas!$C$9,0)
A12: REF588 | B12: Mom Marmorizada | C12: E | D12: 15 | E12: =IFERROR(D12/$D$16,0) | F12: 0 | G12: =ROUND(D12*(1+$B$4),0)+F12 | H12: 85.13 | I12: =G12*H12 | J12: =Premissas!$C$18 | K12: =H12*(1-Premissas!$C$19)*(1-$D$4)*(1-Premissas!$C$20)-J12 | L12: =G12*K12 | M12: =SUMIFS('Log diário'!$D:$D,'Log diário'!$B:$B,$B$2,'Log diário'!$C:$C,$A12) | N12: =SUMIFS('Log diário'!$E:$E,'Log diário'!$B:$B,$B$2,'Log diário'!$C:$C,$A12) | O12: =G12*Premissas!$C$10 | P12: =IFERROR(M12/O12,0) | Q12: =IFERROR(M12/Premissas!$C$8*Premissas!$C$7,0) | R12: =Q12-G12 | S12: =IFERROR(MAX(0,G12-M12)/Premissas!$C$9,0)
A13: REF528 | B13: Wide 528 | C13: E | D13: 15 | E13: =IFERROR(D13/$D$16,0) | F13: 0 | G13: =ROUND(D13*(1+$B$4),0)+F13 | H13: 80.48 | I13: =G13*H13 | J13: =Premissas!$C$18 | K13: =H13*(1-Premissas!$C$19)*(1-$D$4)*(1-Premissas!$C$20)-J13 | L13: =G13*K13 | M13: =SUMIFS('Log diário'!$D:$D,'Log diário'!$B:$B,$B$2,'Log diário'!$C:$C,$A13) | N13: =SUMIFS('Log diário'!$E:$E,'Log diário'!$B:$B,$B$2,'Log diário'!$C:$C,$A13) | O13: =G13*Premissas!$C$10 | P13: =IFERROR(M13/O13,0) | Q13: =IFERROR(M13/Premissas!$C$8*Premissas!$C$7,0) | R13: =Q13-G13 | S13: =IFERROR(MAX(0,G13-M13)/Premissas!$C$9,0)
A14: REF562 | B14: Chocolate | C14: E | D14: 9 | E14: =IFERROR(D14/$D$16,0) | F14: 0 | G14: =ROUND(D14*(1+$B$4),0)+F14 | H14: 85.63 | I14: =G14*H14 | J14: =Premissas!$C$18 | K14: =H14*(1-Premissas!$C$19)*(1-$D$4)*(1-Premissas!$C$20)-J14 | L14: =G14*K14 | M14: =SUMIFS('Log diário'!$D:$D,'Log diário'!$B:$B,$B$2,'Log diário'!$C:$C,$A14) | N14: =SUMIFS('Log diário'!$E:$E,'Log diário'!$B:$B,$B$2,'Log diário'!$C:$C,$A14) | O14: =G14*Premissas!$C$10 | P14: =IFERROR(M14/O14,0) | Q14: =IFERROR(M14/Premissas!$C$8*Premissas!$C$7,0) | R14: =Q14-G14 | S14: =IFERROR(MAX(0,G14-M14)/Premissas!$C$9,0)
A15: CAUDA | B15: SKUs de cauda não detalhados | C15: — | D15: 46 | E15: =IFERROR(D15/$D$16,0) | F15: 0 | G15: =ROUND(D15*(1+$B$4),0)+F15 | H15: 76.05 | I15: =G15*H15 | J15: =Premissas!$C$18 | K15: =H15*(1-Premissas!$C$19)*(1-$D$4)*(1-Premissas!$C$20)-J15 | L15: =G15*K15 | M15: =SUMIFS('Log diário'!$D:$D,'Log diário'!$B:$B,$B$2,'Log diário'!$C:$C,$A15) | N15: =SUMIFS('Log diário'!$E:$E,'Log diário'!$B:$B,$B$2,'Log diário'!$C:$C,$A15) | O15: =G15*Premissas!$C$10 | P15: =IFERROR(M15/O15,0) | Q15: =IFERROR(M15/Premissas!$C$8*Premissas!$C$7,0) | R15: =Q15-G15 | S15: =IFERROR(MAX(0,G15-M15)/Premissas!$C$9,0)
A16: TOTAL | D16: =SUM(D8:D15) | E16: =SUM(E8:E15) | F16: =SUM(F8:F15) | G16: =SUM(G8:G15) | I16: =SUM(I8:I15) | L16: =SUM(L8:L15) | M16: =SUM(M8:M15) | N16: =SUM(N8:N15) | O16: =SUM(O8:O15) | P16: =IFERROR(M16/O16,0) | Q16: =SUM(Q8:Q15) | R16: =SUM(R8:R15) | S16: =SUM(S8:S15)
A17: Σ Hero | D17: =SUMIFS(D8:D15,$C$8:$C$15,"H") | G17: =SUMIFS(G8:G15,$C$8:$C$15,"H") | L17: =SUMIFS(L8:L15,$C$8:$C$15,"H")
A18: Σ Esteira | D18: =SUMIFS(D8:D15,$C$8:$C$15,"E") | G18: =SUMIFS(G8:G15,$C$8:$C$15,"E") | L18: =SUMIFS(L8:L15,$C$8:$C$15,"E")
A20: Ajuste (pç) é a coluna azul onde você força um SKU específico — lançamento do 34, pré-escala do Chocolate, abertura do Baggy. Sem ela, o modelo só escala julho de forma plana, o que contradiz a sua própria estratégia de portfólio.
A21: Índice de pace: 1,00x = exatamente no ritmo da meta. Abaixo de 1,00x = atrasado. Projeção fim = ritmo atual extrapolado até o dia 31.

Sheet Vitrine loja
A1: Vitrine loja — meta por SKU e pace diário
A2: Canal (chave): | B2: Vitrine loja | C2: Superfície: | D2: VITRINE DA LOJA | F2: Atribuição: | G2: Loja / vendedor | I2: Confiança da base jul: | K2: TRANSVERSAL — shop_tab R$89.369 (jul, API 202605) SOBREPÕE card/loja; não somável no NET (lente de superfície, não de último-conteúdo).
A3: Alavanca principal: | B3: A definir — organizar vitrine por curva e coleção
A4: Crescimento vs base: | B4: =Premissas!$C$31 | C4: Comissão afiliada: | D4: =Premissas!$D$31 | F4: CPV padrão: | G4: =Premissas!$C$18
A5: Meta do canal (pç): | B5: =G9 | C5: Meta GMV: | D5: =I9 | F5: Contribuição meta: | G5: =L9 | I5: Índice de pace: | K5: =P9
A7: SKU | B7: Produto | C7: Cl | D7: Base jul (pç) | E7: Mix jul | F7: Ajuste (pç) | G7: Meta (pç) | H7: Preço plan. | I7: Meta GMV | J7: CPV | K7: Contrib./pç | L7: Contrib. meta | M7: Real MTD (pç) | N7: Real MTD (R$) | O7: Esperado MTD | P7: Índice pace | Q7: Projeção fim | R7: Gap vs meta | S7: Pç/dia p/ fechar
A8: — | B8: Sem base de julho para este canal | C8: — | D8: 0 | E8: =IFERROR(D8/$D$9,0) | F8: 0 | G8: =ROUND(D8*(1+$B$4),0)+F8 | H8: 0 | I8: =G8*H8 | J8: =Premissas!$C$18 | K8: =H8*(1-Premissas!$C$19)*(1-$D$4)*(1-Premissas!$C$20)-J8 | L8: =G8*K8 | M8: =SUMIFS('Log diário'!$D:$D,'Log diário'!$B:$B,$B$2,'Log diário'!$C:$C,$A8) | N8: =SUMIFS('Log diário'!$E:$E,'Log diário'!$B:$B,$B$2,'Log diário'!$C:$C,$A8) | O8: =G8*Premissas!$C$10 | P8: =IFERROR(M8/O8,0) | Q8: =IFERROR(M8/Premissas!$C$8*Premissas!$C$7,0) | R8: =Q8-G8 | S8: =IFERROR(MAX(0,G8-M8)/Premissas!$C$9,0)
A9: TOTAL | D9: =SUM(D8:D8) | E9: =SUM(E8:E8) | F9: =SUM(F8:F8) | G9: =SUM(G8:G8) | I9: =SUM(I8:I8) | L9: =SUM(L8:L8) | M9: =SUM(M8:M8) | N9: =SUM(N8:N8) | O9: =SUM(O8:O8) | P9: =IFERROR(M9/O9,0) | Q9: =SUM(Q8:Q8) | R9: =SUM(R8:R8) | S9: =SUM(S8:S8)
A10: Σ Hero | D10: =SUMIFS(D8:D8,$C$8:$C$8,"H") | G10: =SUMIFS(G8:G8,$C$8:$C$8,"H") | L10: =SUMIFS(L8:L8,$C$8:$C$8,"H")
A11: Σ Esteira | D11: =SUMIFS(D8:D8,$C$8:$C$8,"E") | G11: =SUMIFS(G8:G8,$C$8:$C$8,"E") | L11: =SUMIFS(L8:L8,$C$8:$C$8,"E")
A13: Ajuste (pç) é a coluna azul onde você força um SKU específico — lançamento do 34, pré-escala do Chocolate, abertura do Baggy. Sem ela, o modelo só escala julho de forma plana, o que contradiz a sua própria estratégia de portfólio.
A14: Índice de pace: 1,00x = exatamente no ritmo da meta. Abaixo de 1,00x = atrasado. Projeção fim = ritmo atual extrapolado até o dia 31.

Sheet Busca e Mall
A1: Busca e Mall — meta por SKU e pace diário
A2: Canal (chave): | B2: Busca e Mall | C2: Superfície: | D2: BUSCA / MALL / OUTROS | F2: Atribuição: | G2: Misto | I2: Confiança da base jul: | K2: R$0 — nesta atribuição (API 202605) total = seller(live+vídeo+card)+afiliada, resíduo zero. Sem balde separado.
A3: Alavanca principal: | B3: A definir — SEO de título/atributo de produto
A4: Crescimento vs base: | B4: =Premissas!$C$32 | C4: Comissão afiliada: | D4: =Premissas!$D$32 | F4: CPV padrão: | G4: =Premissas!$C$18
A5: Meta do canal (pç): | B5: =G9 | C5: Meta GMV: | D5: =I9 | F5: Contribuição meta: | G5: =L9 | I5: Índice de pace: | K5: =P9
